Workbook

Sheet Part 1
B1: Syntactic Quality | D1: Semantic Quality | F1: Pragmatic Quality
B2: Human | C2: LLM | D2: Human | E2: LLM | F2: Human | G2: LLM
A3: 1 | B3: 0 | C3: 0 | D3: 2 | E3: 9 | F3: 2 | G3: 1
A4: 2 | B4: 3 | C4: 2 | D4: 0 | E4: 3 | F4: 0 | G4: 0
A5: 3 | B5: 0 | C5: 0 | D5: 1 | E5: 14 | F5: 2 | G5: 1
A6: 4 | B6: 0 | C6: 1 | D6: 0 | E6: 5 | F6: 1 | G6: 1
A7: 5 | B7: 1 | C7: 0 | D7: 0 | E7: 6 | F7: 0 | G7: 0 | K7: Syntactic Quality | L7: Semantic Quality | M7: Pragmatic Quality
A8: 6 | B8: 0 | C8: 0 | D8: 7 | E8: 5 | F8: 3 | G8: 3 | J8: Human | K8: =B23 | L8: =D23 | M8: =F23
A9: 7 | B9: 0 | C9: 1 | D9: 0 | E9: 1 | F9: 0 | G9: 2 | J9: LLM | K9: =C23 | L9: =E23 | M9: =G23
A10: 8 | B10: 0 | C10: 1 | D10: 1 | E10: =2 | F10: 1 | G10: 2
A11: 9 | B11: 0 | C11: 1 | D11: 1 | E11: 6 | F11: 4 | G11: 3
A12: 10 | B12: 0 | C12: 2 | D12: 1 | E12: 1 | F12: 1 | G12: 2
A13: 11 | B13: 0 | C13: 1 | D13: 3 | E13: 5 | F13: 2 | G13: 1
A14: 12 | B14: 0 | C14: 1 | D14: 1 | E14: 1 | F14: 0 | G14: 1
A15: 13 | B15: 0 | C15: 0 | D15: 0 | E15: 3 | F15: 1 | G15: 1
A16: 14 | B16: 0 | C16: 0 | D16: 1 | E16: 6 | F16: 1 | G16: 1
A17: 15 | B17: 4 | C17: 1 | D17: 5 | E17: 7 | F17: 0 | G17: 2
A18: 16 | B18: 2 | C18: 2 | D18: 2 | E18: 8 | F18: 2 | G18: 3
A19: 17 | B19: 0 | C19: 0 | D19: 2 | E19: 0 | F19: 1 | G19: 2
A20: 18 | B20: 0 | C20: 2 | D20: 3 | E20: 5 | F20: 1 | G20: 1
A21: 19 | B21: 0 | C21: 1 | D21: 3 | E21: 4 | F21: 0 | G21: 3
A22: 20 | B22: 0 | C22: 2 | D22: 2 | E22: 6 | F22: 0 | G22: 2
A23: Tot | B23: =SUM(B3:B22) | C23: =SUM(C3:C22) | D23: =SUM(D3:D22) | E23: =SUM(E3:E22) | F23: =SUM(F3:F22) | G23: =SUM(G3:G22)

Sheet Part 2 - 1
B2: Given Solution | C2: Human | D2: LLM | E2: Distance Human | F2: Distance LLM
B3: Work Product | C3: Work Product | D3: Work Product | E3: =0 | F3: =0
B4: Work Product .Percent Complete | C4: Work Product .Percent Complete | D4: \ | E4: =SQRT(0^2 + 0^2 + 0^2 + 0^2) | F4: =SQRT(1^2 + 1^2 + 1^2 + 1^2)
B5: Work Product .Description | C5: Work Product .Description | D5: \ | E5: =SQRT(0^2 + 0^2 + 0^2 + 0^2) | F5: =SQRT(1^2 + 1^2 + 1^2 + 1^2)
B6: Work Product .Validate() | C6: Work Product .Validate() | D6: \ | E6: =SQRT(0^2 + 0^2 + 0^2 + 0^2 + 0^2 + 0^2) | F6: =SQRT(1^2 + 1^2 + 1^2 + 1^2 + 0.5^2 + 1^2)
B7: Requirement | C7: Requirement | D7: Requirement | E7: =0 | F7: =0
B8: Requirement .Media | C8: \ | D8: \ | E8: =SQRT(1^2 + 1^2 + 1^2 + 1^2) | F8: =SQRT(1^2 + 1^2 + 1^2 + 1^2)
B9: Requirement .Validate() | C9: \ | D9: Requirement .ValidateWorkProduct() | E9: =SQRT(1^2 + 1^2 + 1^2 + 1^2 + 0.5^2 + 1^2) | F9: =SQRT(0^2 + 0^2 + 0^2 + 1^2 + 0^2 + 0^2)
B10: Requirement .Publish() | C10: Requirement .Publish() | D10: \ | E10: =SQRT(0^2 + 0^2 + 0^2 + 0^2 + 0^2 + 0^2) | F10: =SQRT(1^2 + 1^2 + 1^2 + 1^2 + 0.5^2 + 1^2)
B11: \ | C11: \ | D11: Requirement .percentComplete | E11: =SQRT(0^2 + 0^2 + 0^2 + 0^2 + 0^2 + 0^2) | F11: =SQRT(1^2 + 1^2 + 1^2 + 1^2)
B12: \ | C12: \ | D12: Requirement .Description | E12: =SQRT(0^2 + 0^2 + 0^2 + 0^2 + 0^2 + 0^2) | F12: =SQRT(1^2 + 1^2 + 1^2 + 1^2)
B13: System | C13: System | D13: System | E13: =0 | F13: =0
B14: System .Platform | C14: \ | D14: \ | E14: =SQRT(0^2 + 0^2 + 0^2 + 0^2) | F14: =SQRT(1^2 + 1^2 + 1^2 + 1^2)
B15: System .Validate() | C15: \ | D15: \ | E15: =SQRT(1^2 + 1^2 + 1^2 + 1^2 + 0.5^2 + 1^2) | F15: =SQRT(1^2 + 1^2 + 1^2 + 1^2 + 0.5^2 + 1^2)
B16: System .Deploy() | C16: System .Deploy() | D16: System .Deploy() | E16: =SQRT(0^2 + 0^2 + 0^2 + 0^2 + 0^2 + 0^2) | F16: =SQRT(0^2 + 0^2 + 0^2 + 0^2 + 0^2 + 0^2)
B17: \ | C17: \ | D17: System .PublishRequirements() | E17: =SQRT(0^2 + 0^2 + 0^2 + 0^2 + 0^2 + 0^2) | F17: =SQRT(1^2 + 1^2 + 1^2 + 1^2 + 0.5^2 + 1^2)
B18: Project | C18: Project | D18: Project | E18: =0 | F18: =0
B19: Project .Name | C19: Project .Name | D19: Project .projectID | E19: =SQRT(0^2 + 0^2 + 0^2 + 0^2) | F19: =SQRT(0^2 + 0^2 + 1^2 + 1^2)
B20: Project .Start Date | C20: Project .Start Date | D20: \ | E20: =SQRT(0^2 + 0^2 + 0^2 + 0^2) | F20: =SQRT(1^2 + 1^2 + 1^2 + 1^2)
B21: Project .End Date | C21: Project .End Date | D21: \ | E21: =SQRT(0^2 + 0^2 + 0^2 + 0^2) | F21: =SQRT(1^2 + 1^2 + 1^2 + 1^2)
B22: Manager | C22: Project Manager | D22: Project Manager | E22: =0.5 | F22: =0.5
B23: Manager .Name | C23: Project Manager .Name | D23: Project Manager .Name | E23: =SQRT(0^2 + 0^2 + 0^2 + 0^2) | F23: =SQRT(0^2 + 0^2 + 0^2 + 0^2)
B24: Manager .Phone Number | C24: \ | D24: \ | E24: =SQRT(1^2 + 1^2 + 1^2 + 1^2) | F24: =SQRT(1^2 + 1^2 + 1^2 + 1^2)
B25: Manager .Initiate Project() | C25: ProjectManager .Initiate Project() | D25: ProjectManager .Initiate Project() | E25: =SQRT(0^2 + 0^2 + 0^2 + 0^2 + 0^2 + 0^2) | F25: =SQRT(0^2 + 0^2 + 0^2 + 0^2 + 0^2 + 0^2)
B26: Manager .Terminate Project() | C26: ProjectManager .Terminate Project() | D26: ProjectManager .Terminate Project() | E26: =SQRT(0^2 + 0^2 + 0^2 + 0^2 + 0^2 + 0^2) | F26: =SQRT(0^2 + 0^2 + 0^2 + 0^2 + 0^2 + 0^2)
B27: \ | C27: \ | D27: ProjectManager .startDate | E27: =SQRT(0^2 + 0^2 + 0^2 + 0^2) | F27: =SQRT(1^2 + 1^2 + 1^2 + 1^2)
B28: \ | C28: \ | D28: ProjectManager .endDate | E28: =SQRT(0^2 + 0^2 + 0^2 + 0^2) | F28: =SQRT(1^2 + 1^2 + 1^2 + 1^2)
B29: Team | C29: Team | D29: \ | E29: =0 | F29: =1
B30: Team .Description | C30: Team .Description | D30: \ | E30: =SQRT(0^2 + 0^2 + 0^2 + 0^2) | F30: =SQRT(1^2 + 1^2 + 1^2 + 1^2)
B31: \ | C31: \ | D31: Validation | E31: =SQRT(0^2 + 0^2 + 0^2 + 0^2) | F31: =1
B32: Generalization (Work Product - Requirement) | C32: Generalization (Work Product - Requirement) | D32: Generalization (Work Product - Requirement) | E32: =SQRT(0^2 + 0^2 + 0^2 + 0^2) | F32: =SQRT(1^2 + 1^2 + 0^2 + 0^2)
B33: Generalization (Work Product - System) | C33: Generalization (Work Product - System) | D33: Generalization (Work Product - System) | E33: =SQRT(0^2 + 0^2 + 0^2 + 0^2) | F33: =SQRT(1^2 + 1^2 + 0^2 + 0^2)
B34: Association (Requirement - Project) | C34: Association (Requirement - Project) | D34: Association (Requirement - Project) | E34: =SQRT(0^2 + 0^2 + 0^2 + 0^2) | F34: =SQRT(0^2 + 0^2 + 0^2 + 0^2)
B35: Association (System - Project) | C35: Association (System - Project) | D35: Association (System - Project) | E35: =SQRT(0^2 + 0^2 + 0^2 + 0^2) | F35: =SQRT(0^2 + 0^2 + 0^2 + 0^2)
B36: Association (Project - Manager) | C36: Association (Project - ProjectManager) | D36: Association (Project - ProjectManager) | E36: =SQRT(0^2 + 0^2 + 0^2 + 0^2) | F36: =SQRT(0^2 + 0^2 + 0^2 + 0^2)
B37: Association (Project - Team) | C37: Association (Project - Team) | D37: \ | E37: =SQRT(0^2 + 0^2 + 0^2 + 0^2) | F37: =SQRT(1^2 + 1^2 + 1^2 + 1^2)
B38: Association (Manager - Team) | C38: Association (ProjectManager - Team) | D38: \ | E38: =SQRT(0^2 + 0^2 + 0^2 + 0^2) | F38: =SQRT(1^2 + 1^2 + 1^2 + 1^2)
B39: \ | C39: \ | D39: Association (Work Product - Validation) | E39: =SQRT(0^2 + 0^2 + 0^2 + 0^2) | F39: =SQRT(1^2 + 1^2 + 1^2 + 1^2)
D42: Total Distance | E42: =SQRT(SUMSQ(E3:E39)) | F42: =SQRT(SUMSQ(F3:F39))

Sheet Part 2 - 2
B2: Given Solution | C2: Human | D2: LLM | E2: Distance Human | F2: Distance LLM
B3: Take | C3: Takes | D3: Take | E3: =0.5 | F3: =0
B4: Take .nbr | C4: Takes. natural_numbers | D4: Take .number | E4: =SQRT(0^2 + 0^2 + 0^2 + 0^2) | F4: =SQRT(0^2 + 0^2 + 0^2 + 0^2)
B5: Take .filmed_meters | C5: Takes .filmed_meters | D5: Take .filmLength | E5: =SQRT(0^2 + 0^2 + 0^2 + 0^2) | F5: =SQRT(0^2 + 0^2 + 1^2 + 0^2)
B6: Take .reel | C6: Takes .reel | D6: Take .filmCode | E6: =SQRT(0^2 + 0^2 + 0^2 + 0^2) | F6: =SQRT(0^2 + 0^2 + 1^2 + 0^2)
B7: Setup | C7: Setup | D7: Setup | E7: =0 | F7: =0
B8: Setup .code | C8: Setup .code | D8: Setup .code | E8: =SQRT(0^2 + 0^2 + 0^2 + 0^2) | F8: =SQRT(0^2 + 0^2 + 0^2 + 0^2)
B9: Setup .photographic_pars | C9: Setup .photographic_parameters | D9: Setup .photographicParameters | E9: =SQRT(0^2 + 0^2 + 0^2 + 0^2) | F9: =SQRT(0^2 + 0^2 + 0^2 + 0^2)
B10: \ | C10: \ | D10: Setup .description | E10: =SQRT(0^2 + 0^2 + 0^2 + 0^2) | F10: =SQRT(1^2 + 1^2 + 1^2 + 1^2)
B11: Scene | C11: Scene | D11: Scene | E11: =0 | F11: =0
B12: Scene .code | C12: Scene .code | D12: Scene .code | E12: =SQRT(0^2 + 0^2 + 0^2 + 0^2) | F12: =SQRT(0^2 + 0^2 + 0^2 + 0^2)
B13: Scene .description | C13: Scene .description | D13: Scene .description | E13: =SQRT(0^2 + 0^2 + 0^2 + 0^2) | F13: =SQRT(0^2 + 0^2 + 0^2 + 0^2)
B14: Internal | C14: Internals | D14: Internal | E14: =0.5 | F14: =0
B15: Internal .theater | C15: Internals .teather | D15: \ | E15: =SQRT(0^2 + 0^2 + 0^2 + 0^2) | F15: =SQRT(1^2 + 1^2 + 1^2 + 1^2)
B16: External | C16: Externals | D16: External | E16: =0.5 | F16: =0
B17: External .night_scene | C17: External .night_scene | D17: External .timeofday | E17: =SQRT(0^2 + 0^2 + 0^2 + 0^2) | F17: =SQRT(0^2 + 0^2 + 1^2 + 1^2)
B18: Location | C18: Location | D18: Location | E18: =0 | F18: =0
B19: Location .name | C19: Location .name | D19: Location .code | E19: =SQRT(0^2 + 0^2 + 0^2 + 0^2) | F19: =SQRT(0^2 + 0^2 + 1^2 + 0^2)
B20: Location .address | C20: Location .address | D20: Location .address | E20: =SQRT(0^2 + 0^2 + 0^2 + 0^2) | F20: =SQRT(0^2 + 0^2 + 0^2 + 0^2)
B21: Location .description | C21: Location .description | D21: Location .description | E21: =SQRT(0^2 + 0^2 + 0^2 + 0^2) | F21: =SQRT(0^2 + 0^2 + 0^2 + 0^2)
B22: Association (Take - Setup) | C22: Association (Takes - Setup) | D22: Association (Take - Setup) | E22: =SQRT(0^2 + 0^2 + 0^2 + 0^2) | F22: =SQRT(0^2 + 0^2 + 0^2 + 0^2)
B23: Association (Setup - Scene) | C23: Association (Setup - Scene) | D23: Association (Setup - Scene) | E23: =SQRT(0^2 + 0^2 + 0^2 + 0^2) | F23: =SQRT(0^2 + 0^2 + 0^2 + 0^2)
B24: Generalization (Scene - Internal) | C24: Generalization (Scene - Internals) | D24: Generalization (Scene - Internal) | E24: =SQRT(0^2 + 0^2 + 0^2 + 0^2) | F24: =SQRT(0^2 + 0^2 + 0^2 + 0^2)
B25: Generalization (Scene - Extenal) | C25: Generalization (Scene - Extenals) | D25: Generalization (Scene - Extenal) | E25: =SQRT(0^2 + 0^2 + 0^2 + 0^2) | F25: =SQRT(0^2 + 0^2 + 0^2 + 0^2)
B26: Association (Externals - Location) | C26: Association (External - Location) | D26: Association (External - Location) | E26: =SQRT(0^2 + 0^2 + 0^2 + 0^2) | F26: =SQRT(0^2 + 0^2 + 0^2 + 1^2)
B27: \ | C27: \ | D27: Association (Scene - Internal) | E27: =SQRT(0^2 + 0^2 + 0^2 + 0^2) | F27: =SQRT(1^2 + 1^2 + 1^2 + 1^2)
B28: \ | C28: \ | D28: Association (Scene - External) | E28: =SQRT(0^2 + 0^2 + 0^2 + 0^2) | F28: =SQRT(1^2 + 1^2 + 1^2 + 1^2)
D31: Total Distance | E31: =SQRT(SUMSQ(E3:E28)) | F31: =SQRT(SUMSQ(F3:F28))

Sheet Part 2 - 3
B2: Given Solution | C2: Human | D2: LLM | E2: Distance Human | F2: Distance LLM
B3: Document | C3: Document | D3: Document | E3: =0 | F3: =0
B4: Document .numberofpages | C4: Document .numberofpages | D4: Document .pages | E4: =SQRT(0^2 + 0^2 + 0^2 + 0^2) | F4: =SQRT(0^2 + 0^2 + 0^2 + 1^2)
B5: \ | C5: User | D5: User | E5: =1 | F5: =1
B6: Document .open() | C6: User .open() | D6: User .openDocument() | E6: =SQRT(0^2 + 0^2 + 0^2 + 0^2 + 0^2 + 0^2) | F6: =SQRT(0^2 + 0^2 + 0^2 + 0^2 + 0^2 + 0^2)
B7: Document .save() | C7: User .save() | D7: User .saveDocument() | E7: =SQRT(0^2 + 0^2 + 0^2 + 0^2 + 0^2 + 0^2) | F7: =SQRT(0^2 + 0^2 + 0^2 + 0^2 + 0^2 + 0^2)
B8: Document .print() | C8: User .print() | D8: User .printDocument() | E8: =SQRT(0^2 + 0^2 + 0^2 + 0^2 + 0^2 + 0^2) | F8: =SQRT(0^2 + 0^2 + 0^2 + 0^2 + 0^2 + 0^2)
B9: Document .new() | C9: User .new() | D9: \ | E9: =SQRT(0^2 + 0^2 + 0^2 + 0^2 + 0^2 + 0^2) | F9: =SQRT(1^2 + 1^2 + 1^2 + 1^2 + 0.5^2 + 1^2)
B10: Page | C10: Page | D10: Page | E10: =0 | F10: =0
B11: Page .pageNumber | C11: \ | D11: \ | E11: =SQRT(1^2 + 1^2 + 1^2 + 1^2) | F11: =SQRT(1^2 + 1^2 + 1^2 + 1^2)
B12: Trimming | C12: \ | D12: \ | E12: =0 | F12: =0
B13: Trimming .date | C13: Header/Footer .date | D13: Header/Footer .date | E13: =SQRT(0^2 + 0^2 + 0^2 + 0^2) | F13: =SQRT(0^2 + 0^2 + 0^2 + 0^2)
B14: Trimming .time | C14: Header/Footer .time | D14: Header/Footer .time | E14: =SQRT(0^2 + 0^2 + 0^2 + 0^2) | F14: =SQRT(0^2 + 0^2 + 0^2 + 0^2)
B15: Trimming .pageNumber | C15: Header/Footer .pageNumber | D15: Header/Footer .pageNumber | E15: =SQRT(0^2 + 0^2 + 0^2 + 0^2) | F15: =SQRT(0^2 + 0^2 + 0^2 + 0^2)
B16: \ | C16: Header | D16: Header | E16: =1 | F16: =1
B17: \ | C17: Footer | D17: Footer | E17: =1 | F17: =1
B18: Character | C18: \ | D18: \ | E18: =1 | F18: =1
B19: Character .ASCIICode | C19: \ | D19: \ | E19: =SQRT(1^2 + 1^2 + 1^2 + 1^2) | F19: =SQRT(1^2 + 1^2 + 1^2 + 1^2)
B20: Character .Type | C20: \ | D20: \ | E20: =SQRT(1^2 + 1^2 + 1^2 + 1^2) | F20: =SQRT(1^2 + 1^2 + 1^2 + 1^2)
B21: Table | C21: Table | D21: Table | E21: =0 | F21: =0
B22: Table .rows | C22: Table .rows | D22: Table .rows | E22: =SQRT(0^2 + 0^2 + 0^2 + 0^2) | F22: =SQRT(0^2 + 0^2 + 0^2 + 0^2)
B23: Table .columns | C23: Table .columns | D23: \ | E23: =SQRT(0^2 + 0^2 + 0^2 + 0^2) | F23: =SQRT(1^2 + 1^2 + 1^2 + 1^2)
B24: Picture | C24: Picture | D24: Picture | E24: =0 | F24: =0
B25: Picture .imageType | C25: Picture .imageType | D25: \ | E25: =SQRT(0^2 + 0^2 + 0^2 + 0^2) | F25: =SQRT(1^2 + 1^2 + 1^2 + 1^2)
B26: Picture .imageSize | C26: Picture .imageSize | D26: \ | E26: =SQRT(0^2 + 0^2 + 0^2 + 0^2) | F26: =SQRT(1^2 + 1^2 + 1^2 + 1^2)
B27: Cell | C27: Cell | D27: Cell | E27: =0 | F27: =0
B28: Cell .cellFormat | C28: \ | D28: \ | E28: =SQRT(1^2 + 1^2 + 1^2 + 1^2) | F28: =SQRT(1^2 + 1^2 + 1^2 + 1^2)
B29: \ | C29: Body | D29: Body | E29: =1 | F29: =1
B30: \ | C30: Sentence | D30: Sentence | E30: =1 | F30: =1
B31: \ | C31: Puntuaction | D31: \ | E31: =1 | F31: =0
B32: \ | C32: Word | D32: Word | E32: =1 | F32: =1
B33: \ | C33: \ | D33: ContentItem | E33: =0 | F33: =1
B34: \ | C34: \ | D34: Row | E34: =0 | F34: =1
B35: Composition (Document - Page) | C35: Composition (Document - Page) | D35: Association (Document - Page) | E35: =SQRT(0^2 + 0^2 + 0^2 + 0^2) | F35: =SQRT(0^2 + 0^2 + 1^2 + 1^2)
B36: Aggregation (Page - Trimming) | C36: \ | D36: \ | E36: =SQRT(1^2 + 1^2 + 1^2 + 1^2) | F36: =SQRT(1^2 + 1^2 + 1^2 + 1^2)
B37: Aggregation (Page - Character) | C37: \ | D37: \ | E37: =SQRT(1^2 + 1^2 + 1^2 + 1^2) | F37: =SQRT(1^2 + 1^2 + 1^2 + 1^2)
B38: Aggregation (Page - Table) | C38: \ | D38: \ | E38: =SQRT(1^2 + 1^2 + 1^2 + 1^2) | F38: =SQRT(1^2 + 1^2 + 1^2 + 1^2)
B39: Aggregation (Page - Picture) | C39: \ | D39: \ | E39: =SQRT(1^2 + 1^2 + 1^2 + 1^2) | F39: =SQRT(1^2 + 1^2 + 1^2 + 1^2)
B40: Aggregation (Cell - Character) | C40: \ | D40: \ | E40: =SQRT(1^2 + 1^2 + 1^2 + 1^2) | F40: =SQRT(1^2 + 1^2 + 1^2 + 1^2)
B41: Aggregation (Cell - Picture) | C41: Aggregation (Cell - Picture) | D41: \ | E41: =SQRT(0^2 + 0^2 + 0^2 + 0^2) | F41: =SQRT(1^2 + 1^2 + 1^2 + 1^2)
...

Sheet Part 2 - 4
B2: Given Solution | C2: Human | D2: LLM | E2: Distance Human | F2: Distance LLM
B3: FamilyInsured | C3: Family | D3: Family | E3: =0 | F3: =0
B4: FamilyInsured .NameofFamilyHead | C4: Family .NameofFamilyHead | D4: Family .HeadofFamily | E4: =SQRT(0^2 + 0^2 + 0^2 + 0^2) | F4: =SQRT(0^2 + 0^2 + 0^2 + 0^2)
B5: FamilyInsured .Address | C5: Family .address | D5: \ | E5: =SQRT(0^2 + 0^2 + 0^2 + 0^2) | F5: =SQRT(1^2 + 1^2 + 1^2 + 1^2)
B6: FamilyInsured .Telephone | C6: Family .telephone | D6: \ | E6: =SQRT(0^2 + 0^2 + 0^2 + 0^2) | F6: =SQRT(1^2 + 1^2 + 1^2 + 1^2)
B7: FamilyInsured .InsuranceCarrier | C7: Family .Insurancecarrier | D7: \ | E7: =SQRT(0^2 + 0^2 + 0^2 + 0^2) | F7: =SQRT(1^2 + 1^2 + 1^2 + 1^2)
B8: FamilyInsured .PolicyNumber | C8: Family .PolicyNumber | D8: \ | E8: =SQRT(0^2 + 0^2 + 0^2 + 0^2) | F8: =SQRT(1^2 + 1^2 + 1^2 + 1^2)
B9: Doctor | C9: Doctor | D9: Doctor | E9: =0 | F9: =0
B10: Doctor .Name | C10: Doctor .Name | D10: \ | E10: =SQRT(0^2 + 0^2 + 0^2 + 0^2) | F10: =SQRT(1^2 + 1^2 + 1^2 + 1^2)
B11: Doctor .Specialty | C11: Doctor .Specialty | D11: \ | E11: =SQRT(0^2 + 0^2 + 0^2 + 0^2) | F11: =SQRT(1^2 + 1^2 + 1^2 + 1^2)
B12: Doctor .Address | C12: Doctor .Address | D12: \ | E12: =SQRT(0^2 + 0^2 + 0^2 + 0^2) | F12: =SQRT(1^2 + 1^2 + 1^2 + 1^2)
B13: Doctor .Telephone | C13: Doctor .Telephone | D13: \ | E13: =SQRT(0^2 + 0^2 + 0^2 + 0^2) | F13: =SQRT(1^2 + 1^2 + 1^2 + 1^2)
B14: Doctor .PagerNumber | C14: \ | D14: \ | E14: =SQRT(1^2 + 1^2 + 1^2 + 1^2) | F14: =SQRT(1^2 + 1^2 + 1^2 + 1^2)
B15: Doctor .SSN | C15: \ | D15: \ | E15: =SQRT(1^2 + 1^2 + 1^2 + 1^2) | F15: =SQRT(1^2 + 1^2 + 1^2 + 1^2)
B16: Patient | C16: Patient | D16: Patient | E16: =0 | F16: =0
B17: Patient .Name | C17: Patient .Name | D17: \ | E17: =SQRT(0^2 + 0^2 + 0^2 + 0^2) | F17: =SQRT(1^2 + 1^2 + 1^2 + 1^2)
B18: Patient .Gender | C18: Patient .Gender | D18: \ | E18: =SQRT(0^2 + 0^2 + 0^2 + 0^2) | F18: =SQRT(1^2 + 1^2 + 1^2 + 1^2)
B19: Patient .Birthdate | C19: Patient .Birthdate | D19: \ | E19: =SQRT(0^2 + 0^2 + 0^2 + 0^2) | F19: =SQRT(1^2 + 1^2 + 1^2 + 1^2)
B20: Patient .LastVisitDate | C20: Patient .LastVisitDate | D20: \ | E20: =SQRT(0^2 + 0^2 + 0^2 + 0^2) | F20: =SQRT(1^2 + 1^2 + 1^2 + 1^2)
B21: Patient .Allergies | C21: Patient .Allergies | D21: \ | E21: =SQRT(0^2 + 0^2 + 0^2 + 0^2) | F21: =SQRT(1^2 + 1^2 + 1^2 + 1^2)
B22: Patient .Notes | C22: Patient .Notes | D22: \ | E22: =SQRT(0^2 + 0^2 + 0^2 + 0^2) | F22: =SQRT(1^2 + 1^2 + 1^2 + 1^2)
B23: Visit | C23: Visit | D23: Visit | E23: =0 | F23: =0
B24: Visit .Date | C24: Visit .Date | D24: Visit .Date | E24: =SQRT(0^2 + 0^2 + 0^2 + 0^2) | F24: =SQRT(0^2 + 0^2 + 0^2 + 0^2)
B25: Visit .Weight | C25: \ | D25: \ | E25: =SQRT(1^2 + 1^2 + 1^2 + 1^2) | F25: =SQRT(1^2 + 1^2 + 1^2 + 1^2)
B26: Visit .BloodPressure | C26: \ | D26: \ | E26: =SQRT(1^2 + 1^2 + 1^2 + 1^2) | F26: =SQRT(1^2 + 1^2 + 1^2 + 1^2)
B27: Visit .Temperature | C27: \ | D27: \ | E27: =SQRT(1^2 + 1^2 + 1^2 + 1^2) | F27: =SQRT(1^2 + 1^2 + 1^2 + 1^2)
B28: Visit .Reason | C28: Visit .Reason | D28: \ | E28: =SQRT(0^2 + 0^2 + 0^2 + 0^2) | F28: =SQRT(1^2 + 1^2 + 1^2 + 1^2)
B29: Visit .DiagnosisNotes | C29: Visit .DiagnosisNotes | D29: Visit .diagnosis | E29: =SQRT(0^2 + 0^2 + 0^2 + 0^2) | F29: =SQRT(0^2 + 0^2 + 0^2 + 0^2)
B30: Visit .TreatmentNotes | C30: Visit .TreatmentNotes | D30: Visit .medications | E30: =SQRT(0^2 + 0^2 + 0^2 + 0^2) | F30: =SQRT(0^2 + 0^2 + 0^2 + 0^2)
B31: \ | C31: Receptionist | D31: Receptionist | E31: =1 | F31: =1
B32: \ | C32: Nurse | D32: Nurse | E32: =1 | F32: =1
B33: \ | C33: \ | D33: User | E33: =0 | F33: =1
B34: \ | C34: \ | D34: Person | E34: =0 | F34: =1
B35: Appointment | C35: Appointment | D35: Appointment | E35: =0 | F35: =0
B36: Appointment .Date | C36: Appointment .Date | D36: Appointment .Date | E36: =SQRT(0^2 + 0^2 + 0^2 + 0^2) | F36: =SQRT(0^2 + 0^2 + 0^2 + 0^2)
B37: Appointment .Time | C37: Appointment .Time | D37: Appointment .Time | E37: =SQRT(0^2 + 0^2 + 0^2 + 0^2) | F37: =SQRT(0^2 + 0^2 + 0^2 + 0^2)
B38: Appointment .Reason | C38: Appointment .Reason | D38: \ | E38: =SQRT(0^2 + 0^2 + 0^2 + 0^2) | F38: =SQRT(1^2 + 1^2 + 1^2 + 1^2)
B39: Prescription | C39: Prescription | D39: Medication | E39: =0 | F39: =0.5
B40: Prescription .Date | C40: Prescription .Date | D40: \ | E40: =SQRT(0^2 + 0^2 + 0^2 + 0^2) | F40: =SQRT(1^2 + 1^2 + 1^2 + 1^2)
B41: Prescription .Medication | C41: Prescription .Medication | D41: Medication .name | E41: =SQRT(0^2 + 0^2 + 0^2 + 0^2) | F41: =SQRT(0^2 + 0^2 + 1^2 + 0^2)
...

Sheet Part 2 - 5
B2: Given Solution | C2: Human | D2: LLM | E2: Distance Human | F2: Distance LLM
B3: User | C3: User | D3: User | E3: =0 | F3: =0
B4: User .name | C4: User .firstname | D4: User .name | E4: =SQRT(0^2 + 0^2 + 0^2 + 0^2) | F4: =SQRT(0^2 + 0^2 + 0^2 + 0^2)
B5: User .surname | C5: User .lastname | D5: \ | E5: =SQRT(0^2 + 0^2 + 0^2 + 0^2) | F5: =SQRT(1^2 + 1^2 + 1^2 + 1^2)
B6: Subscriber | C6: Subscriber | D6: Subscriber | E6: =0 | F6: =0
B7: Subscriber .phone | C7: Subscriber .telephone | D7: \ | E7: =SQRT(0^2 + 0^2 + 0^2 + 0^2) | F7: =SQRT(1^2 + 1^2 + 1^2 + 1^2)
B8: Subscriber .address | C8: Subscriber .address | D8: \ | E8: =SQRT(0^2 + 0^2 + 0^2 + 0^2) | F8: =SQRT(1^2 + 1^2 + 1^2 + 1^2)
B9: \ | C9: \ | D9: Subscriber .hireMovie() | E9: \ | F9: =SQRT(1^2 + 1^2 + 1^2 + 1^2 + 0.5^2 + 1^2)
B10: \ | C10: \ | D10: Subscriber .buyMovie() | E10: \ | F10: =SQRT(1^2 + 1^2 + 1^2 + 1^2 + 0.5^2 + 1^2)
B11: Card | C11: Card | D11: Recheargeable Card | E11: =0 | F11: =0
B12: Card .credit | C12: Card .credit | D12: Recheargeable Card .credit | E12: =SQRT(0^2 + 0^2 + 0^2 + 0^2) | F12: =SQRT(0^2 + 0^2 + 0^2 + 0^2)
B13: Card .code | C13: Card .code | D13: Recheargeable Card .cardNumber | E13: =SQRT(0^2 + 0^2 + 0^2 + 0^2) | F13: =SQRT(0^2 + 0^2 + 1^2 + 0^2)
B14: Movie-Shop | C14: Movie-Shop | D14: MovieShopSystem | E14: =0 | F14: =0
B15: Movie-Shop .listmovies() | C15: Movie-Shop .listmovies() | D15: Movie-Shop .browseCatalogue() | E15: =SQRT(0^2 + 0^2 + 0^2 + 0^2 + 0^2 + 0^2) | F15: =SQRT(0^2 + 0^2 + 0^2 + 1^2 + 0^2 + 0^2)
B16: Movie-Shop .order() | C16: Movie-Shop .order() | D16: MovieShopSystem .orderMovie() | E16: =SQRT(0^2 + 0^2 + 0^2 + 0^2 + 0^2 + 0^2) | F16: =SQRT(0^2 + 0^2 + 0^2 + 0^2 + 0^2 + 0^2)
B17: Movie-Shop .subscribe() | C17: Movie-Shop .subscribe() | D17: MovieShopSystem .handleSubscription() | E17: =SQRT(0^2 + 0^2 + 0^2 + 0^2 + 0^2 + 0^2) | F17: =SQRT(0^2 + 0^2 + 0^2 + 0^2 + 0^2 + 0^2)
B18: Order | C18: Order | D18: Order | E18: =0 | F18: =0
B19: Order .date | C19: Order .date | D19: Order .orderDate | E19: =SQRT(0^2 + 0^2 + 0^2 + 0^2) | F19: =SQRT(0^2 + 0^2 + 0^2 + 0^2)
B20: Order .user | C20: Order .user | D20: Order .User | E20: =SQRT(0^2 + 0^2 + 0^2 + 0^2) | F20: =SQRT(0^2 + 0^2 + 0^2 + 0^2)
B21: Movie | C21: Movie | D21: Movie | E21: =0 | F21: =0
B22: Movie .name | C22: Movie .name | D22: Movie .title | E22: =SQRT(0^2 + 0^2 + 0^2 + 0^2) | F22: =SQRT(0^2 + 0^2 + 1^2 + 0^2)
B23: \ | C23: \ | D23: Movie .available | E23: =SQRT(0^2 + 0^2 + 0^2 + 0^2) | F23: =SQRT(1^2 + 1^2 + 1^2 + 1^2)
B24: Movie .type | C24: \ | D24: \ | E24: =SQRT(1^2 + 1^2 + 1^2 + 1^2) | F24: =SQRT(1^2 + 1^2 + 1^2 + 1^2)
B25: Movie-Buy | C25: Movie-Buy | D25: \ | E25: =0 | F25: =SQRT(1^2 + 1^2 + 1^2 + 1^2)
B26: Movie-Buy .status | C26: Movie-Buy .state | D26: \ | E26: =SQRT(0^2 + 0^2 + 0^2 + 0^2) | F26: =SQRT(1^2 + 1^2 + 1^2 + 1^2)
B27: Movie-Buy .Price-Sell | C27: Movie-Buy .sellingprice | D27: \ | E27: =SQRT(0^2 + 0^2 + 0^2 + 0^2) | F27: =SQRT(1^2 + 1^2 + 1^2 + 1^2)
B28: Movie-Rent | C28: Movie-Rent | D28: \ | E28: =0 | F28: =SQRT(1^2 + 1^2 + 1^2 + 1^2)
B29: Movie-Rent .status | C29: Movie-Rent .state | D29: \ | E29: =SQRT(0^2 + 0^2 + 0^2 + 0^2) | F29: =SQRT(1^2 + 1^2 + 1^2 + 1^2)
B30: Movie-Rent .date | C30: Movie-Rent .date | D30: \ | E30: =SQRT(0^2 + 0^2 + 0^2 + 0^2) | F30: =SQRT(1^2 + 1^2 + 1^2 + 1^2)
B31: Movie-Rent .Price | C31: Movie-Rent .rentingprice | D31: \ | E31: =SQRT(0^2 + 0^2 + 0^2 + 0^2) | F31: =SQRT(1^2 + 1^2 + 1^2 + 1^2)
B32: Generalization (User - Subscriber) | C32: Generalization (User - Subscriber) | D32: Generalization (User - Subscriber) | E32: =SQRT(0^2 + 0^2 + 0^2 + 0^2) | F32: =SQRT(0^2 + 0^2 + 0^2 + 0^2)
B33: Association (User - Movie-Shop) | C33: Association (User - Movie-Shop) | D33: \ | E33: =SQRT(0^2 + 0^2 + 0^2 + 0^2) | F33: =SQRT(1^2 + 1^2 + 1^2 + 1^2)
B34: Association (Movie-Shop - Card) | C34: Association (Movie-Shop - Card) | D34: \ | E34: =SQRT(0^2 + 0^2 + 0^2 + 0^2) | F34: =SQRT(1^2 + 1^2 + 1^2 + 1^2)
B35: Association (Subscriber - Card) | C35: Association (Subscriber - Card) | D35: Association (Subscriber - RecheargableCard) | E35: =SQRT(0^2 + 0^2 + 0^2 + 0^2) | F35: =SQRT(0^2 + 0^2 + 0^2 + 0^2)
B36: Aggregation (Movie-Shop - Movie) | C36: Aggregation (Movie-Shop - Movie) | D36: Association (MovieShopSystem - Movie) | E36: =SQRT(0^2 + 0^2 + 0^2 + 0^2) | F36: =SQRT(0^2 + 0^2 + 1^2 + 0^2)
B37: Association (Movie-Shop - Order) | C37: Association (Movie-Shop - Order) | D37: Association (MovieShopSystem - Order) | E37: =SQRT(0^2 + 0^2 + 0^2 + 0^2) | F37: =SQRT(0^2 + 0^2 + 0^2 + 0^2)
B38: Association (Order - Movie-Buy) | C38: Association (Order - Movie-Buy) | D38: \ | E38: =SQRT(0^2 + 0^2 + 0^2 + 0^2) | F38: =SQRT(1^2 + 1^2 + 1^2 + 1^2)
B39: Association (User - Movie-Buy) | C39: Association (User - Movie-Buy) | D39: \ | E39: =SQRT(0^2 + 0^2 + 0^2 + 0^2) | F39: =SQRT(1^2 + 1^2 + 1^2 + 1^2)
B40: Association (Subscriber - Movie-Rent) | C40: Association (Subscriber - Movie-Rent) | D40: \ | E40: =SQRT(0^2 + 0^2 + 0^2 + 0^2) | F40: =SQRT(1^2 + 1^2 + 1^2 + 1^2)
B41: Generalization (Movie - Movie-Rent) | C41: Generalization (Movie - Movie-Rent) | D41: \ | E41: =SQRT(0^2 + 0^2 + 0^2 + 0^2) | F41: =SQRT(1^2 + 1^2 + 1^2 + 1^2)
...

Sheet Part 2 - 6
B2: Given Solution | C2: Human | D2: LLM | E2: Distance Human | F2: Distance LLM
B3: Airline | C3: Airline | D3: Airline | E3: =0 | F3: =0
B4: Airline .ID | C4: Airline .ID | D4: Airline .ID | E4: =SQRT(0^2 + 0^2 + 0^2 + 0^2) | F4: =SQRT(0^2 + 0^2 + 0^2 + 0^2)
B5: Airline .Name | C5: \ | D5: \ | E5: =SQRT(1^2 + 1^2 + 1^2 + 1^2) | F5: =SQRT(1^2 + 1^2 + 1^2 + 1^2)
B6: Aircraft | C6: Aircraft | D6: Aircraft | E6: =0 | F6: =0
B7: Aircraft .Name | C7: Aircraft .Id | D7: \ | E7: =SQRT(0^2 + 0^2 + 1^2 + 0^2) | F7: =SQRT(1^2 + 1^2 + 1^2 + 1^2)
B8: Aircraft .repair | C8: Aircraft .WorkingState | D8: Aircraft .WorkingState | E8: =SQRT(0^2 + 0^2 + 1^2 + 0^2) | F8: =SQRT(0^2 + 0^2 + 1^2 + 0^2)
B9: Aircraft .landed | C9: Aircraft .landed | D9: Aircraft .status | E9: =SQRT(0^2 + 0^2 + 0^2 + 0^2) | F9: =SQRT(0^2 + 0^2 + 1^2 + 0^2)
B10: \ | C10: \ | D10: Aircraft .type | E10: =SQRT(0^2 + 0^2 + 0^2 + 0^2) | F10: =SQRT(1^2 + 1^2 + 1^2 + 1^2)
B11: Flight | C11: Flight | D11: Flight | E11: =0 | F11: =0
B12: Flight .ID | C12: Flight .ID | D12: Flight .ID | E12: =SQRT(0^2 + 0^2 + 0^2 + 0^2) | F12: =SQRT(0^2 + 0^2 + 0^2 + 0^2)
B13: Flight .arrival_time | C13: Flight .arrival_time | D13: Flight .arrival_time | E13: =SQRT(0^2 + 0^2 + 0^2 + 0^2) | F13: =SQRT(0^2 + 0^2 + 0^2 + 0^2)
B14: Flight .departure_time | C14: Flight .departure_time | D14: Flight .departure_time | E14: =SQRT(0^2 + 0^2 + 0^2 + 0^2) | F14: =SQRT(0^2 + 0^2 + 0^2 + 0^2)
B15: Airport | C15: Airport | D15: Airport | E15: =0 | F15: =0
B16: Airport .ID | C16: Airport .Identifier | D16: Airport .code | E16: =SQRT(0^2 + 0^2 + 0^2 + 0^2) | F16: =SQRT(0^2 + 0^2 + 1^2 + 0^2)
B17: Airport .name | C17: \ | D17: Airport .name | E17: =SQRT(1^2 + 1^2 + 1^2 + 1^2) | F17: =SQRT(0^2 + 0^2 + 0^2 + 0^2)
B18: AircraftType | C18: TypeofAircraft | D18: \ | E18: =0 | F18: =1
B19: AircraftType .name | C19: TypeofAircraft .name | D19: \ | E19: =SQRT(0^2 + 0^2 + 0^2 + 0^2) | F19: =SQRT(1^2 + 1^2 + 1^2 + 1^2)
B20: Pilot | C20: Pilot | D20: Pilot | E20: =0 | F20: =0
B21: Pilot .name | C21: Pilot .name | D21: \ | E21: =SQRT(0^2 + 0^2 + 0^2 + 0^2) | F21: =SQRT(1^2 + 1^2 + 1^2 + 1^2)
B22: Pilot 1 | C22: \ | D22: \ | E22: =1 | F22: =1
B23: Pilot 2 | C23: \ | D23: \ | E23: =1 | F23: =1
B24: Pilot 3 | C24: \ | D24: \ | E24: =1 | F24: =1
B25: \ | C25: \ | D25: Company | E25: =0 | F25: =1
B26: Association (Airline - Flight) | C26: Association (Airline - Flight) | D26: Association (Airline - Flight) | E26: =SQRT(0^2 + 0^2 + 0^2 + 1^2) | F26: =SQRT(0^2 + 0^2 + 0^2 + 0^2)
B27: Association (Flight - Airport) | C27: Association (Flight - Airport) | D27: Association (Flight - Airport) | E27: =SQRT(0^2 + 0^2 + 0^2 + 1^2) | F27: =SQRT(0^2 + 0^2 + 0^2 + 0^2)
B28: Association (Airport - Flight) | C28: \ | D28: Association (Airport - Flight) | E28: =SQRT(1^2 + 1^2 + 1^2 + 1^2) | F28: =SQRT(0^2 + 0^2 + 0^2 + 0^2)
B29: Association (Airline - Aircraft) | C29: Association (Airline - Aircraft) | D29: Association (Airline - Aircraft) | E29: =SQRT(0^2 + 0^2 + 0^2 + 1^2) | F29: =SQRT(0^2 + 0^2 + 0^2 + 1^2)
B30: Association (Flight - Aircraft) | C30: Association (Flight - Aircraft) | D30: \ | E30: =SQRT(0^2 + 0^2 + 0^2 + 1^2) | F30: =SQRT(1^2 + 1^2 + 1^2 + 1^2)
B31: Association (Flight - Pilot) | C31: Association (Flight - Pilot) | D31: Association (Flight - Pilot) | E31: =SQRT(0^2 + 0^2 + 0^2 + 0^2) | F31: =SQRT(0^2 + 0^2 + 0^2 + 1^2)
B32: \ | C32: \ | D32: Association (Pilot - Flight) | E32: =SQRT(0^2 + 0^2 + 0^2 + 0^2) | F32: =SQRT(1^2 + 1^2 + 1^2 + 1^2)
B33: Association (Aircraft - Aircraft Type) | C33: Association (Aircraft - TypeofAircraft) | D33: \ | E33: =SQRT(0^2 + 0^2 + 0^2 + 1^2) | F33: =SQRT(1^2 + 1^2 + 1^2 + 1^2)
B34: Association (Aircraft Type - Pilot 3) | C34: \ | D34: \ | E34: =SQRT(1^2 + 1^2 + 1^2 + 1^2) | F34: =SQRT(1^2 + 1^2 + 1^2 + 1^2)
B35: Association (Aircraft Type - Pilot) | C35: Association (TypeofAircraft - Pilot) | D35: \ | E35: =SQRT(0^2 + 0^2 + 0^2 + 1^2) | F35: =SQRT(1^2 + 1^2 + 1^2 + 1^2)
B36: Association (Pilot - Aircraft Type) | C36: \ | D36: \ | E36: =SQRT(1^2 + 1^2 + 1^2 + 1^2) | F36: =SQRT(1^2 + 1^2 + 1^2 + 1^2)
B37: Generalization (Pilot - Pilot1) | C37: \ | D37: \ | E37: =SQRT(1^2 + 1^2 + 1^2 + 1^2) | F37: =SQRT(1^2 + 1^2 + 1^2 + 1^2)
B38: Generalization (Pilot - Pilot2) | C38: \ | D38: \ | E38: =SQRT(1^2 + 1^2 + 1^2 + 1^2) | F38: =SQRT(1^2 + 1^2 + 1^2 + 1^2)
B39: Generalization (Pilot - Pilot3) | C39: \ | D39: \ | E39: =SQRT(1^2 + 1^2 + 1^2 + 1^2) | F39: =SQRT(1^2 + 1^2 + 1^2 + 1^2)
B40: \ | C40: \ | D40: Asssociation (Pilot - Company) | E40: =SQRT(0^2 + 0^2 + 0^2 + 0^2) | F40: =SQRT(1^2 + 1^2 + 1^2 + 1^2)
D43: Total Distance | E43: =SQRT(SUMSQ(E3:E40)) | F43: =SQRT(SUMSQ(F3:F40))

Sheet Part 2 - 7
B2: Given Solution | C2: Human | D2: LLM | E2: Distance Human | F2: Distance LLM
B3: Customer | C3: Customer | D3: Customer | E3: =0 | F3: =0
B4: Customer .Name | C4: Customer .Name | D4: Customer .Name | E4: =SQRT(0^2 + 0^2 + 0^2 + 0^2) | F4: =SQRT(0^2 + 0^2 + 0^2 + 0^2)
B5: Customer .Address | C5: Customer .Address | D5: Customer .Address | E5: =SQRT(0^2 + 0^2 + 0^2 + 0^2) | F5: =SQRT(0^2 + 0^2 + 0^2 + 0^2)
B6: Account | C6: Account | D6: Account | E6: =0 | F6: =0
B7: Account .CashBalance | C7: Account .Balance | D7: Account .Balance | E7: =SQRT(0^2 + 0^2 + 0^2 + 0^2) | F7: =SQRT(0^2 + 0^2 + 0^2 + 0^2)
B8: InvestmentAccount | C8: Investments | D8: InvestmentAccount | E8: =0 | F8: =0
B9: SavingAccount | C9: Savings | D9: SavingsAccount | E9: =0 | F9: =0
B10: SavingAccount .interestRate | C10: Savings .interestrate | D10: SavingsAccount .interestRate | E10: =SQRT(0^2 + 0^2 + 0^2 + 0^2) | F10: =SQRT(0^2 + 0^2 + 0^2 + 0^2)
B11: Stock | C11: Stock | D11: \ | E11: =0 | F11: =1
B12: Stock .ticker | C12: \ | D12: StockOrder .Ticker | E12: =SQRT(1^2 + 1^2 + 1^2 + 1^2) | F12: =SQRT(1^2 + 0^2 + 0^2 + 0^2)
B13: Stock .quantity | C13: Stock .quantity | D13: StockOrder .Quantity | E13: =SQRT(0^2 + 0^2 + 0^2 + 0^2) | F13: =SQRT(1^2 + 0^2 + 0^2 + 0^2)
B14: \ | C14: Stock .price | D14: \ | E14: =SQRT(1^2 + 1^2 + 1^2 + 1^2) | F14: =SQRT(0^2 + 0^2 + 0^2 + 0^2)
B15: StockOrder | C15: StockOrder | D15: StockOrder | E15: =0 | F15: =0
B16: StockOrder .commission | C16: StockOrder .commission | D16: StockOrder .commission | E16: =SQRT(0^2 + 0^2 + 0^2 + 0^2) | F16: =SQRT(0^2 + 0^2 + 0^2 + 0^2)
B17: Association (Customer - Account) | C17: Association (Customer - Account) | D17: Association (Customer - Account) | E17: =SQRT(0^2 + 0^2 + 0^2 + 0^2) | F17: =SQRT(0^2 + 0^2 + 0^2 + 0^2)
B18: Generalization (Account - InvestmentAccount) | C18: Generalization (Account - Investments) | D18: Generalization (Account - InvestmentAccount) | E18: =SQRT(0^2 + 0^2 + 0^2 + 0^2) | F18: =SQRT(0^2 + 0^2 + 0^2 + 0^2)
B19: Generalization (Account - SavingAccount) | C19: Generalization (Account - Savings) | D19: Generalization (Account - SavingAccount) | E19: =SQRT(0^2 + 0^2 + 0^2 + 0^2) | F19: =SQRT(0^2 + 0^2 + 0^2 + 0^2)
B20: Association (InvestmentAccount - Stock) | C20: Association (Investments - Stock) | D20: Association (InvestmentAccount - StockOrder) | E20: =SQRT(0^2 + 0^2 + 0^2 + 0^2) | F20: =SQRT(0^2 + 1^2 + 0^2 + 0^2)
B21: Association (Stock - StockOrder) | C21: Association (Stock - StockOrder) | D21: \ | E21: =SQRT(0^2 + 0^2 + 0^2 + 0^2) | F21: =SQRT(1^2 + 1^2 + 1^2 + 1^2)
D24: Total Distance | E24: =SQRT(SUMSQ(E3:E21)) | F24: =SQRT(SUMSQ(F3:F21))

Sheet Part 2 - 8
B2: Given Solution | C2: Human | D2: LLM | E2: Distance Human | F2: Distance LLM
B3: Animal | C3: Animal | D3: Animal | E3: =0 | F3: =0
B4: Animal . ID | C4: Animal . ID | D4: Animal . ID | E4: =SQRT(0^2 + 0^2 + 0^2 + 0^2) | F4: =SQRT(0^2 + 0^2 + 0^2 + 0^2)
B5: Animal .Name | C5: Animal .Name | D5: Animal .Name | E5: =SQRT(0^2 + 0^2 + 0^2 + 0^2) | F5: =SQRT(0^2 + 0^2 + 0^2 + 0^2)
B6: Owner | C6: Owner | D6: Owner | E6: =0 | F6: =0
B7: Physician | C7: Physician | D7: Physician | E7: =0 | F7: =0
B8: Appointment | C8: Appointment | D8: Appointment | E8: =0 | F8: =0
B9: Appointment .Date | C9: Appointment .StartDate | D9: Appointment .DateandTime | E9: =SQRT(0^2 + 0^2 + 1^2 + 0^2) | F9: =SQRT(0^2 + 0^2 + 1^2 + 0^2)
B10: Appointment .Time | C10: Appointment .StartTime | D10: \ | E10: =SQRT(0^2 + 0^2 + 1^2 + 0^2) | F10: =SQRT(1^2 + 1^2 + 1^2 + 1^2)
B11: Condition | C11: Medical_Condition | D11: Medical_Condition | E11: =0.5 | F11: =0.5
B12: Condition .Common_Name | C12: Medical_Condition .CommonName | D12: Medical_Condition .CommonName | E12: =SQRT(0^2 + 0^2 + 0^2 + 0^2) | F12: =SQRT(0^2 + 0^2 + 0^2 + 0^2)
B13: Condition .Sci_Name | C13: Medical_Condition .ScientificName | D13: Medical_Condition .ScientificName | E13: =SQRT(0^2 + 0^2 + 0^2 + 0^2) | F13: =SQRT(0^2 + 0^2 + 0^2 + 0^2)
B14: Breed | C14: Breed | D14: Breed | E14: =0 | F14: =0
B15: Breed .Name | C15: Breed .Type | D15: Breed .Name | E15: =SQRT(0^2 + 0^2 + 1^2 + 0^2) | F15: =SQRT(0^2 + 0^2 + 0^2 + 0^2)
B16: Person | C16: \ | D16: \ | E16: =1 | F16: 1
B17: Person .ID | C17: Owner/Physician .ID | D17: Owner/Physician .ID | E17: =SQRT(0^2 + 0^2 + 0^2 + 0^2) | F17: =SQRT(0^2 + 0^2 + 0^2 + 0^2)
B18: Person .Name | C18: Owner/Physician .Name | D18: Owner/Physician .Name | E18: =SQRT(0^2 + 0^2 + 0^2 + 0^2) | F18: =SQRT(0^2 + 0^2 + 0^2 + 0^2)
B19: Person .Address | C19: Owner/Physician .Address | D19: Owner/Physician .Address | E19: =SQRT(0^2 + 0^2 + 0^2 + 0^2) | F19: =SQRT(0^2 + 0^2 + 0^2 + 0^2)
B20: Person .Phone | C20: Owner/Physician .PhoneNumber | D20: Owner/Physician .PhoneNumber | E20: =SQRT(0^2 + 0^2 + 1^2 + 0^2) | F20: =SQRT(0^2 + 0^2 + 1^2 + 0^2)
B21: Association (Animal - Owner) | C21: Association (Animal - Owner) | D21: Association (Animal - Owner) | E21: =SQRT(0^2 + 0^2 + 0^2 + 0^2) | F21: =SQRT(0^2 + 0^2 + 0^2 + 1^2)
B22: Association (Animal - Breed) | C22: Association (Animal - Breed) | D22: Association (Animal - Breed) | E22: =SQRT(0^2 + 0^2 + 0^2 + 0^2) | F22: =SQRT(0^2 + 0^2 + 0^2 + 0^2)
B23: Association (Animal - Appointment) | C23: Association (Animal - Appointment) | D23: Association (Animal - Appointment) | E23: =SQRT(0^2 + 0^2 + 0^2 + 0^2) | F23: =SQRT(0^2 + 0^2 + 0^2 + 0^2)
B24: Association (Appointment - Condition) | C24: Association (Appointment - Medical_Condition) | D24: \ | E24: =SQRT(0^2 + 0^2 + 0^2 + 0^2) | F24: =SQRT(1^2 + 1^2 + 1^2 + 1^2)
B25: Association (Breed - Condition) | C25: Association (Breed - Medical_Condition) | D25: Association (Breed - Medical_Condition) | E25: =SQRT(0^2 + 0^2 + 0^2 + 0^2) | F25: =SQRT(0^2 + 0^2 + 0^2 + 0^2)
B26: Association (Appointment - Physician) | C26: Association (Appointment - Physician) | D26: Association (Appointment - Physician) | E26: =SQRT(0^2 + 0^2 + 0^2 + 0^2) | F26: =SQRT(0^2 + 0^2 + 0^2 + 0^2)
B27: Generalization (Owner - Person) | C27: \ | D27: \ | E27: =SQRT(1^2 + 1^2 + 1^2 + 1^2) | F27: =SQRT(1^2 + 1^2 + 1^2 + 1^2)
B28: Generalizzation (Physician - Person) | C28: \ | D28: \ | E28: =SQRT(1^2 + 1^2 + 1^2 + 1^2) | F28: =SQRT(1^2 + 1^2 + 1^2 + 1^2)
B29: \ | C29: Association (Appointment - Owner) | D29: \ | E29: =SQRT(1^2 + 1^2 + 1^2 + 1^2) | F29: =SQRT(0^2 + 0^2 + 0^2 + 0^2)
D32: Total Distance | E32: =SQRT(SUMSQ(E3:E29)) | F32: =SQRT(SUMSQ(F3:F29))

Sheet Part 2 - 9
B2: Given Solution | C2: Human | D2: LLM | E2: Distance Human | F2: Distance LLM
B3: Person | C3: \ | D3: \ | E3: =1 | F3: =1
B4: Person .ID | C4: Employee/Owner .ID | D4: Owner/Employee .ID | E4: =SQRT(0^2 + 0^2 + 0^2 + 0^2) | F4: =SQRT(0^2 + 0^2 + 0^2 + 0^2)
B5: Person .Name | C5: Employee/Owner .Name | D5: Owner/Employee .Name | E5: =SQRT(0^2 + 0^2 + 0^2 + 0^2) | F5: =SQRT(0^2 + 0^2 + 0^2 + 0^2)
B6: Person .Address | C6: Employee/Owner .Address | D6: Owner/Employee .Address | E6: =SQRT(0^2 + 0^2 + 0^2 + 0^2) | F6: =SQRT(0^2 + 0^2 + 0^2 + 0^2)
B7: Employee | C7: Employee | D7: Employee | E7: =0 | F7: =0
B8: Owner | C8: Owner | D8: Owner | E8: =0 | F8: =0
B9: \ | C9: Owner .Phone | D9: Owner .PhoneNumber | E9: =SQRT(1^2 + 1^2 + 1^2 + 1^2) | F9: =SQRT(1^2 + 1^2 + 1^2 + 1^2)
B10: Service | C10: Assembly_Service | D10: AssemblyService | E10: =0.5 | F10: =0.5
B11: Service .Car_Km | C11: Assembly_Service .kmscar | D11: \ | E11: =SQRT(0^2 + 0^2 + 0^2 + 0^2) | F11: =SQRT(1^2 + 1^2 + 1^2 + 1^2)
B12: Service .Hours_spent | C12: Assembly_Service .workhours | D12: AssemblyService .workhours | E12: =SQRT(0^2 + 0^2 + 1^2 + 0^2) | F12: =SQRT(0^2 + 0^2 + 1^2 + 0^2)
B13: Service .Adm_Date | C13: Assembly_Service .AdmissionDate | D13: AssemblyService .AdmissionDate | E13: =SQRT(0^2 + 0^2 + 0^2 + 0^2) | F13: =SQRT(0^2 + 0^2 + 0^2 + 0^2)
B14: Service .Finish_Date | C14: Assembly_Service .FinishDate | D14: AssemblyService .FinishDate | E14: =SQRT(0^2 + 0^2 + 0^2 + 0^2) | F14: =SQRT(0^2 + 0^2 + 0^2 + 0^2)
B15: Part/Acc | C15: Part/Accessory | D15: PartAccessory | E15: =0 | F15: =0
B16: Part/Acc .Serial_No | C16: Part/Accessory .SerialNumber | D16: PartAccessory .SerialNumber | E16: =SQRT(0^2 + 0^2 + 0^2 + 0^2) | F16: =SQRT(0^2 + 0^2 + 0^2 + 0^2)
B17: Part/Acc .Price | C17: Part/Accessory .Price | D17: PartAccessory .Price | E17: =SQRT(0^2 + 0^2 + 0^2 + 0^2) | F17: =SQRT(0^2 + 0^2 + 0^2 + 0^2)
B18: \ | C18: Part/Accessory .category | D18: PartAccessory .Category | E18: =SQRT(1^2 + 1^2 + 1^2 + 1^2) | F18: =SQRT(1^2 + 1^2 + 1^2 + 1^2)
B19: Part Type | C19: \ | D19: \ | E19: =1 | F19: =1
B20: Part Type .Current_Price | C20: \ | D20: \ | E20: =SQRT(1^2 + 1^2 + 1^2 + 1^2) | F20: =SQRT(1^2 + 1^2 + 1^2 + 1^2)
B21: Car | C21: Car | D21: Car | E21: =SQRT(0^2 + 0^2 + 0^2 + 0^2) | F21: =0
B22: Car .Plate | C22: Car .Plate | D22: Car .LicensePlate | E22: =SQRT(0^2 + 0^2 + 0^2 + 0^2) | F22: =SQRT(0^2 + 0^2 + 1^2 + 0^2)
B23: Car .Color | C23: Car .Color | D23: Car .Color | E23: =SQRT(0^2 + 0^2 + 0^2 + 0^2) | F23: =SQRT(0^2 + 0^2 + 0^2 + 0^2)
B24: \ | C24: Car .Model | D24: Car .Model | E24: =SQRT(1^2 + 1^2 + 1^2 + 1^2) | F24: =SQRT(1^2 + 1^2 + 1^2 + 1^2)
B25: Car Model | C25: \ | D25: Car Model | E25: =1 | F25: =0
B26: \ | C26: Car .Make | D26: Car Model .Make | E26: =SQRT(1^2 + 1^2 + 1^2 + 1^2) | F26: =SQRT(1^2 + 1^2 + 1^2 + 1^2)
B27: Make | C27: \ | D27: \ | E27: 1 | F27: =1
B28: Make .Name | C28: \ | D28: \ | E28: =SQRT(1^2 + 1^2 + 1^2 + 1^2) | F28: =SQRT(1^2 + 1^2 + 1^2 + 1^2)
B29: Generalization (Employee - Person) | C29: \ | D29: \ | E29: =SQRT(1^2 + 1^2 + 1^2 + 1^2) | F29: =SQRT(1^2 + 1^2 + 1^2 + 1^2)
B30: Generalization (Owner - Person) | C30: \ | D30: \ | E30: =SQRT(1^2 + 1^2 + 1^2 + 1^2) | F30: =SQRT(1^2 + 1^2 + 1^2 + 1^2)
B31: Association ( Employee - Service) | C31: Association (Employee - Assembly Service) | D31: Association (Employee - Assembly Service) | E31: =SQRT(0^2 + 0^2 + 0^2 + 0^2) | F31: =SQRT(0^2 + 0^2 + 0^2 + 0^2)
B32: Association (Owner - Car) | C32: Association (Owner - Car) | D32: Association (Owner - Car) | E32: =SQRT(0^2 + 0^2 + 0^2 + 1^2) | F32: =SQRT(0^2 + 0^2 + 0^2 + 1^2)
B33: Association (Service - Part/Acc) | C33: Association (Assembly Service - Part/Accessory) | D33: Association (Assembly Service - PartAccessory) | E33: =SQRT(0^2 + 0^2 + 0^2 + 0^2) | F33: =SQRT(0^2 + 0^2 + 0^2 + 1^2)
B34: Association (Car - Car Model) | C34: \ | D34: \ | E34: =SQRT(1^2 + 1^2 + 1^2 + 1^2) | F34: =SQRT(1^2 + 1^2 + 1^2 + 1^2)
B35: Association (Service - Car) | C35: Association (Assembly Service - Car) | D35: Association (Assembly Service - Car) | E35: =SQRT(0^2 + 0^2 + 0^2 + 0^2) | F35: =SQRT(0^2 + 0^2 + 0^2 + 0^2)
B36: Association (Car Model - Make) | C36: \ | D36: \ | E36: =SQRT(1^2 + 1^2 + 1^2 + 1^2) | F36: =SQRT(1^2 + 1^2 + 1^2 + 1^2)
B37: Association (Part/Acc - Part Type) | C37: \ | D37: \ | E37: =SQRT(1^2 + 1^2 + 1^2 + 1^2) | F37: =SQRT(1^2 + 1^2 + 1^2 + 1^2)
B38: Association (Car Model - Part Type) | C38: \ | D38: \ | E38: =SQRT(1^2 + 1^2 + 1^2 + 1^2) | F38: =SQRT(1^2 + 1^2 + 1^2 + 1^2)
B39: \ | C39: Association (Part/Accessory - Car) | D39: \ | E39: =SQRT(0^2 + 0^2 + 0^2 + 0^2) | F39: =SQRT(0^2 + 0^2 + 0^2 + 0^2)
B40: \ | C40: \ | D40: Association (PartAccessory - CarModel) | E40: =SQRT(1^2 + 1^2 + 1^2 + 1^2) | F40: =SQRT(1^2 + 1^2 + 1^2 + 1^2)
D43: Total Distance | E43: =SQRT(SUMSQ(E3:E40)) | F43: =SQRT(SUMSQ(F3:F40))

Sheet Part 2 - 10
B2: Given Solution | C2: Human | D2: LLM | E2: Distance Human | F2: Distance LLM
B3: Person | C3: \ | D3: \ | E3: =1 | F3: =1
B4: Person .Name | C4: Client/Waiter .Name | D4: Client/Waiter .Name | E4: =SQRT(0^2 + 0^2 + 0^2 + 0^2) | F4: =SQRT(0^2 + 0^2 + 0^2 + 0^2)
B5: Person .Address | C5: Client/Waiter .Address | D5: Client/Waiter .Address | E5: =SQRT(0^2 + 0^2 + 0^2 + 0^2) | F5: =SQRT(0^2 + 0^2 + 0^2 + 0^2)
B6: Client | C6: Client | D6: Client | E6: =0 | F6: =0
B7: Client .Tax_ID | C7: Client .Tax_ID | D7: Client .Tax_ID | E7: =SQRT(0^2 + 0^2 + 0^2 + 0^2) | F7: =SQRT(0^2 + 0^2 + 0^2 + 0^2)
B8: Waiter | C8: Waiter | D8: Waiter | E8: =0 | F8: =0
B9: Waiter .ID | C9: Waiter .ID | D9: Waiter .ID | E9: =SQRT(0^2 + 0^2 + 0^2 + 0^2) | F9: =SQRT(0^2 + 0^2 + 0^2 + 0^2)
B10: Waiter .Phone | C10: Waiter .PhoneNumber | D10: Waiter .PhoneNumber | E10: =SQRT(0^2 + 0^2 + 0^2 + 0^2) | F10: =SQRT(0^2 + 0^2 + 0^2 + 0^2)
B11: Meal | C11: Meal | D11: Meal | E11: =0 | F11: =0
B12: Meal .Date | C12: Meal .Date | D12: \ | E12: =SQRT(0^2 + 0^2 + 0^2 + 0^2) | F12: =SQRT(1^2 + 1^2 + 1^2 + 1^2)
B13: Meal .StartTime | C13: Meal .StartTime | D13: Meal .StartDate | E13: =SQRT(0^2 + 0^2 + 0^2 + 0^2) | F13: =SQRT(0^2 + 0^2 + 1^2 + 1^2)
B14: Meal .EndTime | C14: Meal .EndTime | D14: Meal .EndDate | E14: =SQRT(0^2 + 0^2 + 0^2 + 0^2) | F14: =SQRT(0^2 + 0^2 + 1^2 + 1^2)
B15: Table | C15: Table | D15: Table | E15: =0 | F15: =0
B16: Table .ID | C16: Table .ID | D16: Table .ID | E16: =SQRT(0^2 + 0^2 + 0^2 + 0^2) | F16: =SQRT(0^2 + 0^2 + 0^2 + 0^2)
B17: Table .Capacity | C17: Table .nofpeople | D17: Table .MaxCapacity | E17: =SQRT(0^2 + 0^2 + 1^2 + 0^2) | F17: =SQRT(0^2 + 0^2 + 0^2 + 0^2)
B18: Dish | C18: Dish | D18: Dish | E18: =0 | F18: =0
B19: Dish .ID | C19: DIsh .ID | D19: DIsh .ID | E19: =SQRT(0^2 + 0^2 + 0^2 + 0^2) | F19: =SQRT(0^2 + 0^2 + 0^2 + 0^2)
B20: Dish .Name | C20: DIsh .Name | D20: DIsh .Name | E20: =SQRT(0^2 + 0^2 + 0^2 + 0^2) | F20: =SQRT(0^2 + 0^2 + 0^2 + 0^2)
B21: Ingredient | C21: Ingredient | D21: Ingredient | E21: =0 | F21: =0
B22: Ingredient .Name | C22: Ingredient .Name | D22: Ingredient .Name | E22: =SQRT(0^2 + 0^2 + 0^2 + 0^2) | F22: =SQRT(0^2 + 0^2 + 0^2 + 0^2)
B23: Ingredient .Unit | C23: Ingredient .MeasuringUnits | D23: Ingredient .MeasuringUnit | E23: =SQRT(0^2 + 0^2 + 1^2 + 0^2) | F23: =SQRT(0^2 + 0^2 + 1^2 + 0^2)
B24: Ingredient .Stock | C24: Ingredient .Quantity | D24: Ingredient .QuantityinStock | E24: =SQRT(0^2 + 0^2 + 1^2 + 0^2) | F24: =SQRT(0^2 + 0^2 + 1^2 + 0^2)
B25: Generalization (Person - Client) | C25: \ | D25: \ | E25: =SQRT(1^2 + 1^2 + 1^2 + 1^2) | F25: =SQRT(1^2 + 1^2 + 1^2 + 1^2)
B26: Generalization (Person - Waiter) | C26: \ | D26: \ | E26: =SQRT(1^2 + 1^2 + 1^2 + 1^2) | F26: =SQRT(1^2 + 1^2 + 1^2 + 1^2)
B27: Association (Client - Meal) | C27: Association (Client - Meal) | D27: Association (Client - Meal) | E27: =SQRT(0^2 + 0^2 + 0^2 + 0^2) | F27: =SQRT(0^2 + 0^2 + 0^2 + 0^2)
B28: Association (Waiter - Meal) | C28: Association (Waiter - Meal) | D28: Association (Waiter - Meal) | E28: =SQRT(0^2 + 0^2 + 0^2 + 0^2) | F28: =SQRT(0^2 + 0^2 + 0^2 + 0^2)
B29: Association (Meal - Table) | C29: Association (Meal - Table) | D29: Association (Meal - Table) | E29: =SQRT(0^2 + 0^2 + 0^2 + 0^2) | F29: =SQRT(0^2 + 0^2 + 0^2 + 0^2)
B30: Association (Meal - Dish) | C30: Association (Meal - Dish) | D30: Association (Meal - Dish) | E30: =SQRT(0^2 + 0^2 + 0^2 + 1^2) | F30: =SQRT(0^2 + 0^2 + 0^2 + 1^2)
B31: Association (Dish - Ingredient) | C31: Association (Dish - Ingredient) | D31: Association (Dish - Ingredient) | E31: =SQRT(0^2 + 0^2 + 0^2 + 0^2) | F31: =SQRT(0^2 + 0^2 + 0^2 + 1^2)
D34: Total Distance | E34: =SQRT(SUMSQ(E3:E31)) | F34: =SQRT(SUMSQ(F3:F31))

Sheet Part 2 - 11
B2: Given Solution | C2: Human | D2: LLM | E2: Distance Human | F2: Distance LLM
B3: Person | C3: \ | D3: \ | E3: =1 | F3: =1
B4: Person .VAT | C4: Customer/Courier .VAT | D4: Customer/Courier .VATNumber | E4: =SQRT(0^2 + 0^2 + 0^2 + 0^2) | F4: =SQRT(0^2 + 0^2 + 0^2 + 0^2)
B5: Person .Name | C5: Customer/Courier .Name | D5: Customer/Courier .Name | E5: =SQRT(0^2 + 0^2 + 0^2 + 0^2) | F5: =SQRT(0^2 + 0^2 + 0^2 + 0^2)
B6: Person .Phone | C6: Customer/Courier .Phone | D6: Customer/Courier .PhoneNumber | E6: =SQRT(0^2 + 0^2 + 0^2 + 0^2) | F6: =SQRT(0^2 + 0^2 + 0^2 + 0^2)
B7: Customer | C7: Customer | D7: Customer | E7: =0 | F7: =0
B8: Customer .Address | C8: Customer .Address | D8: Customer .Address | E8: =SQRT(0^2 + 0^2 + 0^2 + 0^2) | F8: =SQRT(0^2 + 0^2 + 0^2 + 0^2)
B9: Package | C9: Package | D9: Package | E9: =0 | F9: =0
B10: Package .ID | C10: Package .ID | D10: Package .identifierCode | E10: =SQRT(0^2 + 0^2 + 0^2 + 0^2) | F10: =SQRT(0^2 + 0^2 + 1^2 + 0^2)
B11: Package .Weight | C11: Package .Weight | D11: Package .Weight | E11: =SQRT(0^2 + 0^2 + 0^2 + 0^2) | F11: =SQRT(0^2 + 0^2 + 0^2 + 0^2)
B12: Package .Urgency | C12: Package .Urgent | D12: Package .DeliveryType | E12: =SQRT(0^2 + 0^2 + 0^2 + 0^2) | F12: =SQRT(0^2 + 0^2 + 1^2 + 1^2)
B13: Courier | C13: Courier | D13: Courier | E13: =0 | F13: =0
B14: DeliveryCenter | C14: DeliveryCenter | D14: DeliveryCenter | E14: =0 | F14: =0
B15: DeliveryCenter .Name | C15: DeliveryCenter .Name | D15: DeliveryCenter .Name | E15: =SQRT(0^2 + 0^2 + 0^2 + 0^2) | F15: =SQRT(0^2 + 0^2 + 0^2 + 0^2)
B16: DeliveryCenter .Address | C16: DeliveryCenter .Address | D16: DeliveryCenter .Address | E16: =SQRT(0^2 + 0^2 + 0^2 + 0^2) | F16: =SQRT(0^2 + 0^2 + 0^2 + 0^2)
B17: Generalization (Person - Customer) | C17: \ | D17: \ | E17: =SQRT(1^2 + 1^2 + 1^2 + 1^2) | F17: =SQRT(1^2 + 1^2 + 1^2 + 1^2)
B18: Generalization (Person - Courier) | C18: \ | D18: \ | E18: =SQRT(1^2 + 1^2 + 1^2 + 1^2) | F18: =SQRT(1^2 + 1^2 + 1^2 + 1^2)
B19: Association (Courier - DeliveryCenter) | C19: Association (Courier - DeliveryCenter) | D19: Association (Courier - DeliveryCenter) | E19: =SQRT(0^2 + 0^2 + 0^2 + 0^2) | F19: =SQRT(0^2 + 0^2 + 0^2 + 0^2)
B20: Association (Courier - Package) | C20: Association (Courier - Package) | D20: Association (Courier - Package) | E20: =SQRT(0^2 + 0^2 + 0^2 + 0^2) | F20: =SQRT(0^2 + 0^2 + 0^2 + 1^2)
B21: Association (Customer - DeliveryCenter) | C21: Association (Customer - DeliveryCenter) | D21: Association (Customer - DeliveryCenter) 1 | E21: =SQRT(0^2 + 0^2 + 0^2 + 0^2) | F21: =SQRT(0^2 + 0^2 + 0^2 + 0^2)
B22: Association (Customer - Package) 1 | C22: Association (Customer - Package) | D22: Association (Customer - Package) 1 | E22: =SQRT(0^2 + 0^2 + 0^2 + 1^2) | F22: =SQRT(0^2 + 0^2 + 0^2 + 0^2)
B23: Association (Customer - Package) 2 | C23: \ | D23: Association (Customer - Package) 2 | E23: =SQRT(1^2 + 1^2 + 1^2 + 1^2) | F23: =SQRT(0^2 + 0^2 + 0^2 + 0^2)
B24: Association (DeliveryCenter - Package) 1 | C24: Association (DeliveryCenter - Package) | D24: \ | E24: =SQRT(0^2 + 0^2 + 0^2 + 1^2) | F24: =SQRT(1^2 + 1^2 + 1^2 + 1^2)
B25: Association (DeliveryCenter - Package) 2 | C25: \ | D25: \ | E25: =SQRT(1^2 + 1^2 + 1^2 + 1^2) | F25: =SQRT(1^2 + 1^2 + 1^2 + 1^2)
B26: \ | C26: Association (Courier - Customer) | D26: \ | E26: =SQRT(1^2 + 1^2 + 1^2 + 1^2) | F26: =SQRT(0^2 + 0^2 + 0^2 + 0^2)
B27: \ | C27: Association (Customer - Customer) | D27: \ | E27: =SQRT(1^2 + 1^2 + 1^2 + 1^2) | F27: =SQRT(0^2 + 0^2 + 0^2 + 0^2)
B28: \ | C28: \ | D28: Association (Customer - DeliveryCenter) 2 | E28: =SQRT(0^2 + 0^2 + 0^2 + 0^2) | F28: =SQRT(1^2 + 1^2 + 1^2 + 1^2)
D31: Total Distance | E31: =SQRT(SUMSQ(E3:E28)) | F31: =SQRT(SUMSQ(F3:F28))

Sheet Part 2 - 12
B2: Given Solution | C2: Human | D2: LLM | E2: Distance Human | F2: Distance LLM
B3: Store | C3: Store | D3: Store | E3: =0 | F3: =0
B4: Store .Name | C4: \ | D4: \ | E4: =SQRT(1^2 + 1^2 + 1^2 + 1^2) | F4: =SQRT(1^2 + 1^2 + 1^2 + 1^2)
B5: Store .Address | C5: Store .Address | D5: Store .Address | E5: =SQRT(0^2 + 0^2 + 0^2 + 0^2) | F5: =SQRT(0^2 + 0^2 + 0^2 + 0^2)
B6: Store .FAX | C6: Store .FAX | D6: Store .FAXnumber | E6: =SQRT(0^2 + 0^2 + 0^2 + 0^2) | F6: =SQRT(0^2 + 0^2 + 0^2 + 0^2)
B7: Order | C7: Order | D7: Order | E7: =0 | F7: =0
B8: Order .Number | C8: Order .Number | D8: Order .OrderNumber | E8: =SQRT(0^2 + 0^2 + 0^2 + 0^2) | F8: =SQRT(0^2 + 0^2 + 0^2 + 0^2)
B9: Order .Date | C9: Order .Date | D9: Order .Date | E9: =SQRT(0^2 + 0^2 + 0^2 + 0^2) | F9: =SQRT(0^2 + 0^2 + 0^2 + 0^2)
B10: Piece | C10: Piece of Furniture | D10: FurniturePiece | E10: =0.5 | F10: =0.5
B11: Piece .Ref | C11: Piece of Furniture .Reference | D11: FurniturePiece .Reference | E11: =SQRT(0^2 + 0^2 + 0^2 + 0^2) | F11: =SQRT(0^2 + 0^2 + 0^2 + 0^2)
B12: Piece .Price | C12: Piece of Furniture .Price | D12: FurniturePiece .SellingPrice | E12: =SQRT(0^2 + 0^2 + 0^2 + 0^2) | F12: =SQRT(0^2 + 0^2 + 1^2 + 0^2)
B13: \ | C13: Piece of Furniture .type | D13: FurniturePiece .Type | E13: =SQRT(1^2 + 1^2 + 1^2 + 1^2) | F13: =SQRT(1^2 + 1^2 + 1^2 + 1^2)
B14: Line | C14: Furniture Line | D14: Furniture Line | E14: =0.5 | F14: =0.5
B15: Line .Type | C15: Furniture Line .Name | D15: Furniture Line .Name | E15: =SQRT(0^2 + 0^2 + 1^2 + 0^2) | F15: =SQRT(0^2 + 0^2 + 1^2 + 0^2)
B16: Component | C16: Component | D16: Component | E16: =0 | F16: =0
B17: Component .Code | C17: Component .NumericalCode | D17: Component .NumericalCode | E17: =SQRT(0^2 + 0^2 + 0^2 + 0^2) | F17: =SQRT(0^2 + 0^2 + 0^2 + 0^2)
B18: Component .Price | C18: Component .Price | D18: Component .ManufacturingPrice | E18: =SQRT(0^2 + 0^2 + 0^2 + 0^2) | F18: =SQRT(0^2 + 0^2 + 1^2 + 0^2)
B19: \ | C19: \ | D19: Component .Type | E19: =SQRT(0^2 + 0^2 + 0^2 + 0^2) | F19: =SQRT(1^2 + 1^2 + 1^2 + 1^2)
B20: ComponentType | C20: ComponentType | D20: \ | E20: =0 | F20: =SQRT(1^2 + 1^2 + 1^2 + 1^2)
B21: ComponentType .Name | C21: ComponentType .Name | D21: \ | E21: =SQRT(0^2 + 0^2 + 0^2 + 0^2) | F21: =SQRT(1^2 + 1^2 + 1^2 + 1^2)
B22: Association (Store - Order) | C22: Association (Store - Order) | D22: Association (Store - Order) | E22: =SQRT(0^2 + 0^2 + 0^2 + 0^2) | F22: =SQRT(0^2 + 0^2 + 0^2 + 0^2)
B23: Association (Order - Piece) | C23: Association (Order - Piece of Furniture) | D23: Association (Order - FurniturePiece) | E23: =SQRT(0^2 + 0^2 + 0^2 + 0^2) | F23: =SQRT(0^2 + 0^2 + 0^2 + 0^2)
B24: Association (Piece - Line) | C24: Association (Piece of Furniture - Furniture Line) | D24: Association (FurniturePiece - Furniture Line) | E24: =SQRT(0^2 + 0^2 + 0^2 + 0^2) | F24: =SQRT(0^2 + 0^2 + 0^2 + 0^2)
B25: Association (Piece - Component) | C25: Association (Piece of Furniture - Component) | D25: Association (FurniturePiece - Component) | E25: =SQRT(0^2 + 0^2 + 0^2 + 0^2) | F25: =SQRT(0^2 + 0^2 + 0^2 + 1^2)
B26: Association (Component - ComponentType) | C26: Association (Component - ComponentType) | D26: \ | E26: =SQRT(0^2 + 0^2 + 0^2 + 0^2) | F26: =SQRT(1^2 + 1^2 + 1^2 + 1^2)
B27: \ | C27: Association (Piece of Furniture - Store) | D27: \ | E27: =SQRT(1^2 + 1^2 + 1^2 + 1^2) | F27: 0
D30: Total Distance | E30: =SQRT(SUMSQ(E3:E27)) | F30: =SQRT(SUMSQ(F3:F27))

Sheet Part 2 - 13
B2: Given Solution | C2: Human | D2: LLM | E2: Distance Human | F2: Distance LLM
B3: Person | C3: \ | D3: \ | E3: =1 | F3: =1
B4: Person .FirstName | C4: Worker .FirstName | D4: Worker .Name | E4: =SQRT(0^2 + 0^2 + 0^2 + 0^2) | F4: =SQRT(0^2 + 0^2 + 1^2 + 0^2)
B5: Person .Surname | C5: Worker .LastName | D5: \ | E5: =SQRT(0^2 + 0^2 + 0^2 + 0^2) | F5: =SQRT(1^2 + 1^2 + 1^2 + 1^2)
B6: Person .Address | C6: Worker/Client .Address | D6: Worker/Client .Address | E6: =SQRT(0^2 + 0^2 + 0^2 + 0^2) | F6: =SQRT(0^2 + 0^2 + 0^2 + 0^2)
B7: Client | C7: Client | D7: Client | E7: =0 | F7: =0
B8: Client .Phone | C8: Client .Phone | D8: Client .PhoneNumber | E8: =SQRT(0^2 + 0^2 + 0^2 + 0^2) | F8: =SQRT(0^2 + 0^2 + 0^2 + 0^2)
B9: Client .Contact_Person | C9: Client .Contact_Person | D9: Client .Contact_Person | E9: =SQRT(0^2 + 0^2 + 0^2 + 0^2) | F9: =SQRT(0^2 + 0^2 + 0^2 + 0^2)
B10: \ | C10: Client. Name | D10: Client. Name | E10: =SQRT(1^2 + 1^2 + 1^2 + 1^2) | F10: =SQRT(1^2 + 1^2 + 1^2 + 1^2)
B11: Worker | C11: Worker | D11: Worker | E11: =0 | F11: =0
B12: Worker .Birth_Date | C12: Worker .Birth_Date | D12: Worker .BirthDate | E12: =SQRT(0^2 + 0^2 + 0^2 + 0^2) | F12: =SQRT(0^2 + 0^2 + 0^2 + 0^2)
B13: Skill | C13: Skill | D13: \ | E13: =0 | F13: =1
B14: Skill .Name | C14: Skill .Name | D14: Worker .Skills | E14: =SQRT(0^2 + 0^2 + 0^2 + 0^2) | F14: =SQRT(0^2 + 0^2 + 1^2 + 1^2)
B15: Machine | C15: Machine | D15: Machine | E15: =0 | F15: =0
B16: Machine .Serial | C16: Machine .SerialNumber | D16: Machine .SerialNumber | E16: =SQRT(0^2 + 0^2 + 0^2 + 0^2) | F16: =SQRT(0^2 + 0^2 + 0^2 + 0^2)
B17: Machine .Make | C17: Machine .Make | D17: Machine .Make | E17: =SQRT(0^2 + 0^2 + 0^2 + 0^2) | F17: =SQRT(0^2 + 0^2 + 0^2 + 0^2)
B18: Machine .Model | C18: Machine .Model | D18: Machine .Model | E18: =SQRT(0^2 + 0^2 + 0^2 + 0^2) | F18: =SQRT(0^2 + 0^2 + 0^2 + 0^2)
B19: Machine .Purchase_Date | C19: Machine .Purchase_Date | D19: Machine .Purchase_Date | E19: =SQRT(0^2 + 0^2 + 0^2 + 0^2) | F19: =SQRT(0^2 + 0^2 + 0^2 + 0^2)
B20: Product_Type | C20: Product_Type | D20: Product_Type | E20: =0 | F20: =0
B21: Product_Type .Material | C21: Product_Type .Material | D21: Product_Type .Material | E21: =SQRT(0^2 + 0^2 + 0^2 + 0^2) | F21: =SQRT(0^2 + 0^2 + 0^2 + 0^2)
B22: Product_Type .Weight | C22: Product_Type .Weight | D22: Product_Type .Weight | E22: =SQRT(0^2 + 0^2 + 0^2 + 0^2) | F22: =SQRT(0^2 + 0^2 + 0^2 + 0^2)
B23: Product | C23: Product | D23: Product | E23: =0 | F23: =0
B24: Product .ID | C24: Product .ID | D24: Product .ID | E24: =SQRT(0^2 + 0^2 + 0^2 + 0^2) | F24: =SQRT(0^2 + 0^2 + 0^2 + 0^2)
B25: Product .Name | C25: Product .Name | D25: \ | E25: =SQRT(0^2 + 0^2 + 0^2 + 0^2) | F25: =SQRT(1^2 + 1^2 + 1^2 + 1^2)
B26: Purchase Order | C26: Order | D26: Purchase Order | E26: =0.5 | F26: =0
B27: Purchase Order .Number | C27: Order .Number | D27: Purchase Order .OrderNumber | E27: =SQRT(0^2 + 0^2 + 0^2 + 0^2) | F27: =SQRT(0^2 + 0^2 + 0^2 + 0^2)
B28: Purchase Order .Date | C28: Order .Date | D28: Purchase Order. dateMade | E28: =SQRT(0^2 + 0^2 + 0^2 + 0^2) | F28: =SQRT(0^2 + 0^2 + 0^2 + 0^2)
B29: Purchase Order .Expected_Del | C29: Order .Expected_Delivery_Date | D29: Purchase Order .ExpectedDeliveryDate | E29: =SQRT(0^2 + 0^2 + 0^2 + 0^2) | F29: =SQRT(0^2 + 0^2 + 0^2 + 0^2)
B30: Purchase Order .Actual_Del | C30: Order .Actual_Delivery_Date | D30: Purchase Order .ActualDeliveryDate | E30: =SQRT(0^2 + 0^2 + 0^2 + 0^2) | F30: =SQRT(0^2 + 0^2 + 0^2 + 0^2)
B31: Generalization (Person - Client) | C31: \ | D31: \ | E31: =SQRT(1^2 + 1^2 + 1^2 + 1^2) | F31: =SQRT(1^2 + 1^2 + 1^2 + 1^2)
B32: Generalization (Person - Worker) | C32: \ | D32: \ | E32: =SQRT(1^2 + 1^2 + 1^2 + 1^2) | F32: =SQRT(1^2 + 1^2 + 1^2 + 1^2)
B33: Association ( Client - Purchase Order) | C33: Association ( Client - Order) | D33: Association (Client - Purchase Order) | E33: =SQRT(0^2 + 0^2 + 0^2 + 0^2) | F33: =SQRT(0^2 + 0^2 + 0^2 + 0^2)
B34: Association (Worker - Skill) | C34: Association (Worker - Skill) | D34: \ | E34: =SQRT(0^2 + 0^2 + 0^2 + 0^2) | F34: =SQRT(1^2 + 1^2 + 1^2 + 1^2)
B35: Association (Worker - Machine) | C35: Association (Worker - Machine) | D35: Association (Worker - Machine) | E35: =SQRT(0^2 + 0^2 + 0^2 + 0^2) | F35: =SQRT(0^2 + 0^2 + 0^2 + 1^2)
B36: Association (Machine - Product_Type) | C36: Association (Machine - Product_Type) | D36: \ | E36: =SQRT(0^2 + 0^2 + 0^2 + 0^2) | F36: =SQRT(1^2 + 1^2 + 1^2 + 1^2)
B37: Association (Product_Type - Product) | C37: Association (Product_Type - Product) | D37: Association (Product_Type - Product) | E37: =SQRT(0^2 + 0^2 + 0^2 + 0^2) | F37: =SQRT(0^2 + 0^2 + 0^2 + 0^2)
B38: Association (Product - Purchase Order) | C38: Association (Product - Order) | D38: Association (Product - Purchase Order) | E38: =SQRT(0^2 + 0^2 + 0^2 + 0^2) | F38: =SQRT(0^2 + 0^2 + 0^2 + 0^2)
B39: \ | C39: \ | D39: Association (Worker - Product) | E39: =SQRT(0^2 + 0^2 + 0^2 + 0^2) | F39: =SQRT(1^2 + 1^2 + 1^2 + 1^2)
D42: Total Distance | E42: =SQRT(SUMSQ(E3:E39)) | F42: =SQRT(SUMSQ(F3:F39))

Sheet Part 2 - 14
B2: Given Solution | C2: Human | D2: LLM | E2: Distance Human | F2: Distance LLM
B3: Client | C3: Client | D3: Client | E3: =0 | F3: =0
B4: Client .Nin | C4: Client .Nin | D4: Client .Nin | E4: =SQRT(0^2 + 0^2 + 0^2 + 0^2) | F4: =SQRT(0^2 + 0^2 + 0^2 + 0^2)
B5: Client .Tin | C5: Client .Tin | D5: Client .Tin | E5: =SQRT(0^2 + 0^2 + 0^2 + 0^2) | F5: =SQRT(0^2 + 0^2 + 0^2 + 0^2)
B6: Client. Name | C6: Client. Name | D6: Client. Name | E6: =SQRT(0^2 + 0^2 + 0^2 + 0^2) | F6: =SQRT(0^2 + 0^2 + 0^2 + 0^2)
B7: Client .Address | C7: Client .Address | D7: Client .Address | E7: =SQRT(0^2 + 0^2 + 0^2 + 0^2) | F7: =SQRT(0^2 + 0^2 + 0^2 + 0^2)
B8: Reservation | C8: Reservation | D8: Reservation | E8: =0 | F8: =0
B9: Reservation .Pickup_Day | C9: Reservation .Pickup_Day | D9: Reservation .pickupDate | E9: =SQRT(0^2 + 0^2 + 0^2 + 0^2) | F9: =SQRT(0^2 + 0^2 + 1^2 + 0^2)
B10: Reservation .Return_Day | C10: Reservation .Return_Day | D10: \ | E10: =SQRT(0^2 + 0^2 + 0^2 + 0^2) | F10: =SQRT(1^2 + 1^2 + 1^2 + 1^2)
B11: \ | C11: \ | D11: Reservation .reservationID | E11: =SQRT(0^2 + 0^2 + 0^2 + 0^2) | F11: =SQRT(1^2 + 1^2 + 1^2 + 1^2)
B12: \ | C12: \ | D12: Reservation .clientNIN | E12: =SQRT(0^2 + 0^2 + 0^2 + 0^2) | F12: =SQRT(1^2 + 1^2 + 1^2 + 1^2)
B13: \ | C13: \ | D13: Reservation .modelName | E13: =SQRT(0^2 + 0^2 + 0^2 + 0^2) | F13: =SQRT(1^2 + 1^2 + 1^2 + 1^2)
B14: \ | C14: \ | D14: Reservation .StoreName | E14: =SQRT(0^2 + 0^2 + 0^2 + 0^2) | F14: =SQRT(1^2 + 1^2 + 1^2 + 1^2)
B15: Bicycle | C15: Bicycle | D15: Bicycle | E15: =0 | F15: =0
B16: Bicycle .Number | C16: Bicycle .ID | D16: Bicycle .bicycleID | E16: =SQRT(0^2 + 0^2 + 1^2 + 0^2) | F16: =SQRT(0^2 + 0^2 + 1^2 + 0^2)
B17: \ | C17: \ | D17: Bicycle .modelName | E17: =SQRT(0^2 + 0^2 + 0^2 + 0^2) | F17: =SQRT(1^2 + 1^2 + 1^2 + 1^2)
B18: BicycleModel | C18: BicycleModel | D18: BicycleModel | E18: =0 | F18: =0
B19: BicycleModel .Name | C19: BicycleModel .Name | D19: Bicycle .modelName | E19: =SQRT(0^2 + 0^2 + 0^2 + 0^2) | F19: =SQRT(0^2 + 0^2 + 1^2 + 0^2)
B20: BicycleModel .Type | C20: \ | D20: BicycleModel .Type | E20: =SQRT(1^2 + 1^2 + 1^2 + 1^2) | F20: =SQRT(0^2 + 0^2 + 0^2 + 0^2)
B21: BicycleModel .No_Gears | C21: BicycleModel .No_Gears | D21: BicycleModel .NumberofGears | E21: =SQRT(0^2 + 0^2 + 0^2 + 0^2) | F21: =SQRT(0^2 + 0^2 + 0^2 + 0^2)
B22: Store | C22: Store | D22: Store | E22: =0 | F22: =0
B23: Store .Name | C23: Store .Name | D23: Store .storeName | E23: =SQRT(0^2 + 0^2 + 0^2 + 0^2) | F23: =SQRT(0^2 + 0^2 + 0^2 + 0^2)
B24: Store .Address | C24: Store .Address | D24: Store .Address | E24: =SQRT(0^2 + 0^2 + 0^2 + 0^2) | F24: =SQRT(0^2 + 0^2 + 0^2 + 0^2)
B25: \ | C25: Type | D25: \ | E25: =SQRT(1^2 + 1^2 + 1^2 + 1^2) | F25: =SQRT(0^2 + 0^2 + 0^2 + 0^2)
B26: \ | C26: Road | D26: \ | E26: =SQRT(1^2 + 1^2 + 1^2 + 1^2) | F26: =SQRT(0^2 + 0^2 + 0^2 + 0^2)
B27: \ | C27: Mountain | D27: \ | E27: =SQRT(1^2 + 1^2 + 1^2 + 1^2) | F27: =SQRT(0^2 + 0^2 + 0^2 + 0^2)
B28: \ | C28: BMX | D28: \ | E28: =SQRT(1^2 + 1^2 + 1^2 + 1^2) | F28: =SQRT(0^2 + 0^2 + 0^2 + 0^2)
B29: \ | C29: Hybrid | D29: \ | E29: =SQRT(1^2 + 1^2 + 1^2 + 1^2) | F29: =SQRT(0^2 + 0^2 + 0^2 + 0^2)
B30: \ | C30: \ | D30: Rental | E30: =SQRT(0^2 + 0^2 + 0^2 + 0^2) | F30: =SQRT(1^2 + 1^2 + 1^2 + 1^2)
B31: \ | C31: \ | D31: Rental .rentalID | E31: =SQRT(0^2 + 0^2 + 0^2 + 0^2) | F31: =SQRT(1^2 + 1^2 + 1^2 + 1^2)
B32: \ | C32: \ | D32: Rental .bicycleID | E32: =SQRT(0^2 + 0^2 + 0^2 + 0^2) | F32: =SQRT(1^2 + 1^2 + 1^2 + 1^2)
